DEBUG:h5py._conv:Creating converter from 3 to 5
WARNING:werkzeug: * Debugger is active!
INFO:werkzeug: * Debugger PIN: 912-154-751
INFO:werkzeug:127.0.0.1 - - [09/Nov/2023 15:49:49] "GET / HTTP/1.1" 200 -
INFO:werkzeug:127.0.0.1 - - [09/Nov/2023 15:49:49] "[33mGET /path_to_facebook_icon.png HTTP/1.1[0m" 404 -
INFO:werkzeug:127.0.0.1 - - [09/Nov/2023 15:49:49] "[33mGET /path_to_twitter_icon.png HTTP/1.1[0m" 404 -
INFO:werkzeug:127.0.0.1 - - [09/Nov/2023 15:49:49] "[33mGET /path_to_instagram_icon.png HTTP/1.1[0m" 404 -
INFO:werkzeug:127.0.0.1 - - [09/Nov/2023 15:49:49] "[36mGET /static/css/main.css HTTP/1.1[0m" 304 -
INFO:werkzeug:127.0.0.1 - - [09/Nov/2023 15:49:58] "[35m[1mPOST /predict HTTP/1.1[0m" 500 -
INFO:werkzeug: * Detected change in 'c:\\Users\\Karthikeya\\PycharmProjects\\project_AI\\app.py', reloading
DEBUG:h5py._conv:Creating converter from 3 to 5
WARNING:werkzeug: * Debugger is active!
INFO:werkzeug: * Debugger PIN: 912-154-751
INFO:werkzeug:127.0.0.1 - - [09/Nov/2023 15:51:18] "GET / HTTP/1.1" 200 -
INFO:werkzeug:127.0.0.1 - - [09/Nov/2023 15:51:18] "[33mGET /path_to_facebook_icon.png HTTP/1.1[0m" 404 -
INFO:werkzeug:127.0.0.1 - - [09/Nov/2023 15:51:18] "[33mGET /path_to_twitter_icon.png HTTP/1.1[0m" 404 -
INFO:werkzeug:127.0.0.1 - - [09/Nov/2023 15:51:18] "[33mGET /path_to_instagram_icon.png HTTP/1.1[0m" 404 -
INFO:werkzeug:127.0.0.1 - - [09/Nov/2023 15:51:18] "[36mGET /static/css/main.css HTTP/1.1[0m" 304 -
INFO:werkzeug:127.0.0.1 - - [09/Nov/2023 15:51:26] "[35m[1mPOST /predict HTTP/1.1[0m" 500 -
INFO:werkzeug: * Detected change in 'c:\\Users\\Karthikeya\\PycharmProjects\\project_AI\\app.py', reloading
DEBUG:h5py._conv:Creating converter from 3 to 5
WARNING:werkzeug: * Debugger is active!
INFO:werkzeug: * Debugger PIN: 912-154-751
INFO:werkzeug:127.0.0.1 - - [09/Nov/2023 15:53:42] "GET / HTTP/1.1" 200 -
INFO:werkzeug:127.0.0.1 - - [09/Nov/2023 15:53:42] "[33mGET /path_to_facebook_icon.png HTTP/1.1[0m" 404 -
INFO:werkzeug:127.0.0.1 - - [09/Nov/2023 15:53:42] "[33mGET /path_to_twitter_icon.png HTTP/1.1[0m" 404 -
INFO:werkzeug:127.0.0.1 - - [09/Nov/2023 15:53:42] "[33mGET /path_to_instagram_icon.png HTTP/1.1[0m" 404 -
INFO:werkzeug:127.0.0.1 - - [09/Nov/2023 15:53:42] "[36mGET /static/css/main.css HTTP/1.1[0m" 304 -
INFO:werkzeug:127.0.0.1 - - [09/Nov/2023 15:53:50] "POST /predict HTTP/1.1" 200 -
INFO:werkzeug:127.0.0.1 - - [09/Nov/2023 15:54:48] "GET / HTTP/1.1" 200 -
INFO:werkzeug:127.0.0.1 - - [09/Nov/2023 15:54:48] "[33mGET /path_to_facebook_icon.png HTTP/1.1[0m" 404 -
INFO:werkzeug:127.0.0.1 - - [09/Nov/2023 15:54:48] "[36mGET /static/css/main.css HTTP/1.1[0m" 304 -
INFO:werkzeug:127.0.0.1 - - [09/Nov/2023 15:54:48] "[33mGET /path_to_twitter_icon.png HTTP/1.1[0m" 404 -
INFO:werkzeug:127.0.0.1 - - [09/Nov/2023 15:54:48] "[33mGET /path_to_instagram_icon.png HTTP/1.1[0m" 404 -
INFO:werkzeug:127.0.0.1 - - [09/Nov/2023 15:54:55] "POST /predict HTTP/1.1" 200 -
INFO:werkzeug: * Detected change in 'c:\\Users\\Karthikeya\\PycharmProjects\\project_AI\\app.py', reloading
DEBUG:h5py._conv:Creating converter from 3 to 5
WARNING:werkzeug: * Debugger is active!
INFO:werkzeug: * Debugger PIN: 912-154-751
INFO:werkzeug:127.0.0.1 - - [09/Nov/2023 15:56:00] "GET / HTTP/1.1" 200 -
INFO:werkzeug:127.0.0.1 - - [09/Nov/2023 15:56:00] "[33mGET /path_to_facebook_icon.png HTTP/1.1[0m" 404 -
INFO:werkzeug:127.0.0.1 - - [09/Nov/2023 15:56:00] "[33mGET /path_to_twitter_icon.png HTTP/1.1[0m" 404 -
INFO:werkzeug:127.0.0.1 - - [09/Nov/2023 15:56:00] "[33mGET /path_to_instagram_icon.png HTTP/1.1[0m" 404 -
INFO:werkzeug:127.0.0.1 - - [09/Nov/2023 15:56:00] "[36mGET /static/css/main.css HTTP/1.1[0m" 304 -
INFO:werkzeug:127.0.0.1 - - [09/Nov/2023 15:56:08] "POST /predict HTTP/1.1" 200 -
INFO:werkzeug: * Detected change in 'c:\\Users\\Karthikeya\\PycharmProjects\\project_AI\\app.py', reloading
DEBUG:h5py._conv:Creating converter from 3 to 5
WARNING:werkzeug: * Debugger is active!
INFO:werkzeug: * Debugger PIN: 912-154-751
INFO:werkzeug:127.0.0.1 - - [09/Nov/2023 15:57:15] "GET / HTTP/1.1" 200 -
INFO:werkzeug:127.0.0.1 - - [09/Nov/2023 15:57:15] "[33mGET /path_to_facebook_icon.png HTTP/1.1[0m" 404 -
INFO:werkzeug:127.0.0.1 - - [09/Nov/2023 15:57:15] "[33mGET /path_to_twitter_icon.png HTTP/1.1[0m" 404 -
INFO:werkzeug:127.0.0.1 - - [09/Nov/2023 15:57:15] "[33mGET /path_to_instagram_icon.png HTTP/1.1[0m" 404 -
INFO:werkzeug:127.0.0.1 - - [09/Nov/2023 15:57:15] "[36mGET /static/css/main.css HTTP/1.1[0m" 304 -
INFO:werkzeug:127.0.0.1 - - [09/Nov/2023 15:57:22] "POST /predict HTTP/1.1" 200 -
INFO:werkzeug: * Detected change in 'c:\\Users\\Karthikeya\\PycharmProjects\\project_AI\\app.py', reloading
DEBUG:h5py._conv:Creating converter from 3 to 5
WARNING:werkzeug: * Debugger is active!
INFO:werkzeug: * Debugger PIN: 912-154-751
INFO:werkzeug:127.0.0.1 - - [09/Nov/2023 15:58:26] "GET / HTTP/1.1" 200 -
INFO:werkzeug:127.0.0.1 - - [09/Nov/2023 15:58:26] "[33mGET /path_to_facebook_icon.png HTTP/1.1[0m" 404 -
INFO:werkzeug:127.0.0.1 - - [09/Nov/2023 15:58:26] "[33mGET /path_to_twitter_icon.png HTTP/1.1[0m" 404 -
INFO:werkzeug:127.0.0.1 - - [09/Nov/2023 15:58:26] "[33mGET /path_to_instagram_icon.png HTTP/1.1[0m" 404 -
INFO:werkzeug:127.0.0.1 - - [09/Nov/2023 15:58:26] "[36mGET /static/css/main.css HTTP/1.1[0m" 304 -
ERROR:root:Error during prediction: in user code:

    File "C:\Users\Karthikeya\AppData\Local\Programs\Python\Python310\lib\site-packages\keras\src\engine\training.py", line 2416, in predict_function  *
        return step_function(self, iterator)
    File "C:\Users\Karthikeya\AppData\Local\Programs\Python\Python310\lib\site-packages\keras\src\engine\training.py", line 2401, in step_function  **
        outputs = model.distribute_strategy.run(run_step, args=(data,))
    File "C:\Users\Karthikeya\AppData\Local\Programs\Python\Python310\lib\site-packages\keras\src\engine\training.py", line 2389, in run_step  **
        outputs = model.predict_step(data)
    File "C:\Users\Karthikeya\AppData\Local\Programs\Python\Python310\lib\site-packages\keras\src\engine\training.py", line 2357, in predict_step
        return self(x, training=False)
    File "C:\Users\Karthikeya\AppData\Local\Programs\Python\Python310\lib\site-packages\keras\src\utils\traceback_utils.py", line 70, in error_handler
        raise e.with_traceback(filtered_tb) from None
    File "C:\Users\Karthikeya\AppData\Local\Programs\Python\Python310\lib\site-packages\keras\src\engine\input_spec.py", line 298, in assert_input_compatibility
        raise ValueError(

    ValueError: Input 0 of layer "model_2" is incompatible with the layer: expected shape=(None, 224, 224, 3), found shape=(None, 64, 64, 3)

ERROR:root:Error in prediction route: in user code:

    File "C:\Users\Karthikeya\AppData\Local\Programs\Python\Python310\lib\site-packages\keras\src\engine\training.py", line 2416, in predict_function  *
        return step_function(self, iterator)
    File "C:\Users\Karthikeya\AppData\Local\Programs\Python\Python310\lib\site-packages\keras\src\engine\training.py", line 2401, in step_function  **
        outputs = model.distribute_strategy.run(run_step, args=(data,))
    File "C:\Users\Karthikeya\AppData\Local\Programs\Python\Python310\lib\site-packages\keras\src\engine\training.py", line 2389, in run_step  **
        outputs = model.predict_step(data)
    File "C:\Users\Karthikeya\AppData\Local\Programs\Python\Python310\lib\site-packages\keras\src\engine\training.py", line 2357, in predict_step
        return self(x, training=False)
    File "C:\Users\Karthikeya\AppData\Local\Programs\Python\Python310\lib\site-packages\keras\src\utils\traceback_utils.py", line 70, in error_handler
        raise e.with_traceback(filtered_tb) from None
    File "C:\Users\Karthikeya\AppData\Local\Programs\Python\Python310\lib\site-packages\keras\src\engine\input_spec.py", line 298, in assert_input_compatibility
        raise ValueError(

    ValueError: Input 0 of layer "model_2" is incompatible with the layer: expected shape=(None, 224, 224, 3), found shape=(None, 64, 64, 3)

INFO:werkzeug:127.0.0.1 - - [09/Nov/2023 15:58:34] "POST /predict HTTP/1.1" 200 -
INFO:werkzeug:127.0.0.1 - - [09/Nov/2023 16:01:07] "GET / HTTP/1.1" 200 -
INFO:werkzeug:127.0.0.1 - - [09/Nov/2023 16:01:08] "[33mGET /path_to_facebook_icon.png HTTP/1.1[0m" 404 -
INFO:werkzeug:127.0.0.1 - - [09/Nov/2023 16:01:08] "[36mGET /static/css/main.css HTTP/1.1[0m" 304 -
INFO:werkzeug:127.0.0.1 - - [09/Nov/2023 16:01:08] "[33mGET /path_to_twitter_icon.png HTTP/1.1[0m" 404 -
INFO:werkzeug:127.0.0.1 - - [09/Nov/2023 16:01:08] "[33mGET /path_to_instagram_icon.png HTTP/1.1[0m" 404 -
ERROR:root:Error during prediction: in user code:

    File "C:\Users\Karthikeya\AppData\Local\Programs\Python\Python310\lib\site-packages\keras\src\engine\training.py", line 2416, in predict_function  *
        return step_function(self, iterator)
    File "C:\Users\Karthikeya\AppData\Local\Programs\Python\Python310\lib\site-packages\keras\src\engine\training.py", line 2401, in step_function  **
        outputs = model.distribute_strategy.run(run_step, args=(data,))
    File "C:\Users\Karthikeya\AppData\Local\Programs\Python\Python310\lib\site-packages\keras\src\engine\training.py", line 2389, in run_step  **
        outputs = model.predict_step(data)
    File "C:\Users\Karthikeya\AppData\Local\Programs\Python\Python310\lib\site-packages\keras\src\engine\training.py", line 2357, in predict_step
        return self(x, training=False)
    File "C:\Users\Karthikeya\AppData\Local\Programs\Python\Python310\lib\site-packages\keras\src\utils\traceback_utils.py", line 70, in error_handler
        raise e.with_traceback(filtered_tb) from None
    File "C:\Users\Karthikeya\AppData\Local\Programs\Python\Python310\lib\site-packages\keras\src\engine\input_spec.py", line 298, in assert_input_compatibility
        raise ValueError(

    ValueError: Input 0 of layer "model_2" is incompatible with the layer: expected shape=(None, 224, 224, 3), found shape=(None, 64, 64, 3)

ERROR:root:Error in prediction route: in user code:

    File "C:\Users\Karthikeya\AppData\Local\Programs\Python\Python310\lib\site-packages\keras\src\engine\training.py", line 2416, in predict_function  *
        return step_function(self, iterator)
    File "C:\Users\Karthikeya\AppData\Local\Programs\Python\Python310\lib\site-packages\keras\src\engine\training.py", line 2401, in step_function  **
        outputs = model.distribute_strategy.run(run_step, args=(data,))
    File "C:\Users\Karthikeya\AppData\Local\Programs\Python\Python310\lib\site-packages\keras\src\engine\training.py", line 2389, in run_step  **
        outputs = model.predict_step(data)
    File "C:\Users\Karthikeya\AppData\Local\Programs\Python\Python310\lib\site-packages\keras\src\engine\training.py", line 2357, in predict_step
        return self(x, training=False)
    File "C:\Users\Karthikeya\AppData\Local\Programs\Python\Python310\lib\site-packages\keras\src\utils\traceback_utils.py", line 70, in error_handler
        raise e.with_traceback(filtered_tb) from None
    File "C:\Users\Karthikeya\AppData\Local\Programs\Python\Python310\lib\site-packages\keras\src\engine\input_spec.py", line 298, in assert_input_compatibility
        raise ValueError(

    ValueError: Input 0 of layer "model_2" is incompatible with the layer: expected shape=(None, 224, 224, 3), found shape=(None, 64, 64, 3)

INFO:werkzeug:127.0.0.1 - - [09/Nov/2023 16:01:14] "POST /predict HTTP/1.1" 200 -
INFO:werkzeug:127.0.0.1 - - [09/Nov/2023 16:02:18] "GET / HTTP/1.1" 200 -
INFO:werkzeug:127.0.0.1 - - [09/Nov/2023 16:02:18] "[33mGET /path_to_twitter_icon.png HTTP/1.1[0m" 404 -
INFO:werkzeug:127.0.0.1 - - [09/Nov/2023 16:02:18] "[33mGET /path_to_facebook_icon.png HTTP/1.1[0m" 404 -
INFO:werkzeug:127.0.0.1 - - [09/Nov/2023 16:02:18] "[36mGET /static/css/main.css HTTP/1.1[0m" 304 -
INFO:werkzeug:127.0.0.1 - - [09/Nov/2023 16:02:18] "[33mGET /path_to_instagram_icon.png HTTP/1.1[0m" 404 -
INFO:werkzeug:127.0.0.1 - - [09/Nov/2023 16:02:18] "[36mGET /static/js/main.js HTTP/1.1[0m" 304 -
ERROR:root:Error during prediction: in user code:

    File "C:\Users\Karthikeya\AppData\Local\Programs\Python\Python310\lib\site-packages\keras\src\engine\training.py", line 2416, in predict_function  *
        return step_function(self, iterator)
    File "C:\Users\Karthikeya\AppData\Local\Programs\Python\Python310\lib\site-packages\keras\src\engine\training.py", line 2401, in step_function  **
        outputs = model.distribute_strategy.run(run_step, args=(data,))
    File "C:\Users\Karthikeya\AppData\Local\Programs\Python\Python310\lib\site-packages\keras\src\engine\training.py", line 2389, in run_step  **
        outputs = model.predict_step(data)
    File "C:\Users\Karthikeya\AppData\Local\Programs\Python\Python310\lib\site-packages\keras\src\engine\training.py", line 2357, in predict_step
        return self(x, training=False)
    File "C:\Users\Karthikeya\AppData\Local\Programs\Python\Python310\lib\site-packages\keras\src\utils\traceback_utils.py", line 70, in error_handler
        raise e.with_traceback(filtered_tb) from None
    File "C:\Users\Karthikeya\AppData\Local\Programs\Python\Python310\lib\site-packages\keras\src\engine\input_spec.py", line 298, in assert_input_compatibility
        raise ValueError(

    ValueError: Input 0 of layer "model_2" is incompatible with the layer: expected shape=(None, 224, 224, 3), found shape=(None, 64, 64, 3)

ERROR:root:Error in prediction route: in user code:

    File "C:\Users\Karthikeya\AppData\Local\Programs\Python\Python310\lib\site-packages\keras\src\engine\training.py", line 2416, in predict_function  *
        return step_function(self, iterator)
    File "C:\Users\Karthikeya\AppData\Local\Programs\Python\Python310\lib\site-packages\keras\src\engine\training.py", line 2401, in step_function  **
        outputs = model.distribute_strategy.run(run_step, args=(data,))
    File "C:\Users\Karthikeya\AppData\Local\Programs\Python\Python310\lib\site-packages\keras\src\engine\training.py", line 2389, in run_step  **
        outputs = model.predict_step(data)
    File "C:\Users\Karthikeya\AppData\Local\Programs\Python\Python310\lib\site-packages\keras\src\engine\training.py", line 2357, in predict_step
        return self(x, training=False)
    File "C:\Users\Karthikeya\AppData\Local\Programs\Python\Python310\lib\site-packages\keras\src\utils\traceback_utils.py", line 70, in error_handler
        raise e.with_traceback(filtered_tb) from None
    File "C:\Users\Karthikeya\AppData\Local\Programs\Python\Python310\lib\site-packages\keras\src\engine\input_spec.py", line 298, in assert_input_compatibility
        raise ValueError(

    ValueError: Input 0 of layer "model_2" is incompatible with the layer: expected shape=(None, 224, 224, 3), found shape=(None, 64, 64, 3)

INFO:werkzeug:127.0.0.1 - - [09/Nov/2023 16:02:25] "POST /predict HTTP/1.1" 200 -
ERROR:root:Error during prediction: in user code:

    File "C:\Users\Karthikeya\AppData\Local\Programs\Python\Python310\lib\site-packages\keras\src\engine\training.py", line 2416, in predict_function  *
        return step_function(self, iterator)
    File "C:\Users\Karthikeya\AppData\Local\Programs\Python\Python310\lib\site-packages\keras\src\engine\training.py", line 2401, in step_function  **
        outputs = model.distribute_strategy.run(run_step, args=(data,))
    File "C:\Users\Karthikeya\AppData\Local\Programs\Python\Python310\lib\site-packages\keras\src\engine\training.py", line 2389, in run_step  **
        outputs = model.predict_step(data)
    File "C:\Users\Karthikeya\AppData\Local\Programs\Python\Python310\lib\site-packages\keras\src\engine\training.py", line 2357, in predict_step
        return self(x, training=False)
    File "C:\Users\Karthikeya\AppData\Local\Programs\Python\Python310\lib\site-packages\keras\src\utils\traceback_utils.py", line 70, in error_handler
        raise e.with_traceback(filtered_tb) from None
    File "C:\Users\Karthikeya\AppData\Local\Programs\Python\Python310\lib\site-packages\keras\src\engine\input_spec.py", line 298, in assert_input_compatibility
        raise ValueError(

    ValueError: Input 0 of layer "model_2" is incompatible with the layer: expected shape=(None, 224, 224, 3), found shape=(None, 64, 64, 3)

ERROR:root:Error in prediction route: in user code:

    File "C:\Users\Karthikeya\AppData\Local\Programs\Python\Python310\lib\site-packages\keras\src\engine\training.py", line 2416, in predict_function  *
        return step_function(self, iterator)
    File "C:\Users\Karthikeya\AppData\Local\Programs\Python\Python310\lib\site-packages\keras\src\engine\training.py", line 2401, in step_function  **
        outputs = model.distribute_strategy.run(run_step, args=(data,))
    File "C:\Users\Karthikeya\AppData\Local\Programs\Python\Python310\lib\site-packages\keras\src\engine\training.py", line 2389, in run_step  **
        outputs = model.predict_step(data)
    File "C:\Users\Karthikeya\AppData\Local\Programs\Python\Python310\lib\site-packages\keras\src\engine\training.py", line 2357, in predict_step
        return self(x, training=False)
    File "C:\Users\Karthikeya\AppData\Local\Programs\Python\Python310\lib\site-packages\keras\src\utils\traceback_utils.py", line 70, in error_handler
        raise e.with_traceback(filtered_tb) from None
    File "C:\Users\Karthikeya\AppData\Local\Programs\Python\Python310\lib\site-packages\keras\src\engine\input_spec.py", line 298, in assert_input_compatibility
        raise ValueError(

    ValueError: Input 0 of layer "model_2" is incompatible with the layer: expected shape=(None, 224, 224, 3), found shape=(None, 64, 64, 3)

INFO:werkzeug:127.0.0.1 - - [09/Nov/2023 16:02:25] "POST /predict HTTP/1.1" 200 -
INFO:werkzeug:127.0.0.1 - - [09/Nov/2023 16:03:51] "GET / HTTP/1.1" 200 -
INFO:werkzeug:127.0.0.1 - - [09/Nov/2023 16:03:51] "[36mGET /static/css/main.css HTTP/1.1[0m" 304 -
INFO:werkzeug:127.0.0.1 - - [09/Nov/2023 16:03:51] "[33mGET /path_to_facebook_icon.png HTTP/1.1[0m" 404 -
INFO:werkzeug:127.0.0.1 - - [09/Nov/2023 16:03:51] "[33mGET /path_to_twitter_icon.png HTTP/1.1[0m" 404 -
INFO:werkzeug:127.0.0.1 - - [09/Nov/2023 16:03:51] "[33mGET /path_to_instagram_icon.png HTTP/1.1[0m" 404 -
INFO:werkzeug:127.0.0.1 - - [09/Nov/2023 16:03:51] "[36mGET /static/js/main.js HTTP/1.1[0m" 304 -
ERROR:root:Error during prediction: in user code:

    File "C:\Users\Karthikeya\AppData\Local\Programs\Python\Python310\lib\site-packages\keras\src\engine\training.py", line 2416, in predict_function  *
        return step_function(self, iterator)
    File "C:\Users\Karthikeya\AppData\Local\Programs\Python\Python310\lib\site-packages\keras\src\engine\training.py", line 2401, in step_function  **
        outputs = model.distribute_strategy.run(run_step, args=(data,))
    File "C:\Users\Karthikeya\AppData\Local\Programs\Python\Python310\lib\site-packages\keras\src\engine\training.py", line 2389, in run_step  **
        outputs = model.predict_step(data)
    File "C:\Users\Karthikeya\AppData\Local\Programs\Python\Python310\lib\site-packages\keras\src\engine\training.py", line 2357, in predict_step
        return self(x, training=False)
    File "C:\Users\Karthikeya\AppData\Local\Programs\Python\Python310\lib\site-packages\keras\src\utils\traceback_utils.py", line 70, in error_handler
        raise e.with_traceback(filtered_tb) from None
    File "C:\Users\Karthikeya\AppData\Local\Programs\Python\Python310\lib\site-packages\keras\src\engine\input_spec.py", line 298, in assert_input_compatibility
        raise ValueError(

    ValueError: Input 0 of layer "model_2" is incompatible with the layer: expected shape=(None, 224, 224, 3), found shape=(None, 64, 64, 3)

ERROR:root:Error in prediction route: in user code:

    File "C:\Users\Karthikeya\AppData\Local\Programs\Python\Python310\lib\site-packages\keras\src\engine\training.py", line 2416, in predict_function  *
        return step_function(self, iterator)
    File "C:\Users\Karthikeya\AppData\Local\Programs\Python\Python310\lib\site-packages\keras\src\engine\training.py", line 2401, in step_function  **
        outputs = model.distribute_strategy.run(run_step, args=(data,))
    File "C:\Users\Karthikeya\AppData\Local\Programs\Python\Python310\lib\site-packages\keras\src\engine\training.py", line 2389, in run_step  **
        outputs = model.predict_step(data)
    File "C:\Users\Karthikeya\AppData\Local\Programs\Python\Python310\lib\site-packages\keras\src\engine\training.py", line 2357, in predict_step
        return self(x, training=False)
    File "C:\Users\Karthikeya\AppData\Local\Programs\Python\Python310\lib\site-packages\keras\src\utils\traceback_utils.py", line 70, in error_handler
        raise e.with_traceback(filtered_tb) from None
    File "C:\Users\Karthikeya\AppData\Local\Programs\Python\Python310\lib\site-packages\keras\src\engine\input_spec.py", line 298, in assert_input_compatibility
        raise ValueError(

    ValueError: Input 0 of layer "model_2" is incompatible with the layer: expected shape=(None, 224, 224, 3), found shape=(None, 64, 64, 3)

INFO:werkzeug:127.0.0.1 - - [09/Nov/2023 16:04:36] "POST /predict HTTP/1.1" 200 -
INFO:werkzeug:127.0.0.1 - - [09/Nov/2023 16:06:43] "GET / HTTP/1.1" 200 -
INFO:werkzeug:127.0.0.1 - - [09/Nov/2023 16:06:43] "[33mGET /path_to_facebook_icon.png HTTP/1.1[0m" 404 -
INFO:werkzeug:127.0.0.1 - - [09/Nov/2023 16:06:43] "[36mGET /static/css/main.css HTTP/1.1[0m" 304 -
INFO:werkzeug:127.0.0.1 - - [09/Nov/2023 16:06:43] "[33mGET /path_to_twitter_icon.png HTTP/1.1[0m" 404 -
INFO:werkzeug:127.0.0.1 - - [09/Nov/2023 16:06:43] "[33mGET /path_to_instagram_icon.png HTTP/1.1[0m" 404 -
INFO:werkzeug:127.0.0.1 - - [09/Nov/2023 16:06:43] "[36mGET /static/js/main.js HTTP/1.1[0m" 304 -
ERROR:root:Error during prediction: in user code:

    File "C:\Users\Karthikeya\AppData\Local\Programs\Python\Python310\lib\site-packages\keras\src\engine\training.py", line 2416, in predict_function  *
        return step_function(self, iterator)
    File "C:\Users\Karthikeya\AppData\Local\Programs\Python\Python310\lib\site-packages\keras\src\engine\training.py", line 2401, in step_function  **
        outputs = model.distribute_strategy.run(run_step, args=(data,))
    File "C:\Users\Karthikeya\AppData\Local\Programs\Python\Python310\lib\site-packages\keras\src\engine\training.py", line 2389, in run_step  **
        outputs = model.predict_step(data)
    File "C:\Users\Karthikeya\AppData\Local\Programs\Python\Python310\lib\site-packages\keras\src\engine\training.py", line 2357, in predict_step
        return self(x, training=False)
    File "C:\Users\Karthikeya\AppData\Local\Programs\Python\Python310\lib\site-packages\keras\src\utils\traceback_utils.py", line 70, in error_handler
        raise e.with_traceback(filtered_tb) from None
    File "C:\Users\Karthikeya\AppData\Local\Programs\Python\Python310\lib\site-packages\keras\src\engine\input_spec.py", line 298, in assert_input_compatibility
        raise ValueError(

    ValueError: Input 0 of layer "model_2" is incompatible with the layer: expected shape=(None, 224, 224, 3), found shape=(None, 64, 64, 3)

ERROR:root:Error in prediction route: in user code:

    File "C:\Users\Karthikeya\AppData\Local\Programs\Python\Python310\lib\site-packages\keras\src\engine\training.py", line 2416, in predict_function  *
        return step_function(self, iterator)
    File "C:\Users\Karthikeya\AppData\Local\Programs\Python\Python310\lib\site-packages\keras\src\engine\training.py", line 2401, in step_function  **
        outputs = model.distribute_strategy.run(run_step, args=(data,))
    File "C:\Users\Karthikeya\AppData\Local\Programs\Python\Python310\lib\site-packages\keras\src\engine\training.py", line 2389, in run_step  **
        outputs = model.predict_step(data)
    File "C:\Users\Karthikeya\AppData\Local\Programs\Python\Python310\lib\site-packages\keras\src\engine\training.py", line 2357, in predict_step
        return self(x, training=False)
    File "C:\Users\Karthikeya\AppData\Local\Programs\Python\Python310\lib\site-packages\keras\src\utils\traceback_utils.py", line 70, in error_handler
        raise e.with_traceback(filtered_tb) from None
    File "C:\Users\Karthikeya\AppData\Local\Programs\Python\Python310\lib\site-packages\keras\src\engine\input_spec.py", line 298, in assert_input_compatibility
        raise ValueError(

    ValueError: Input 0 of layer "model_2" is incompatible with the layer: expected shape=(None, 224, 224, 3), found shape=(None, 64, 64, 3)

INFO:werkzeug:127.0.0.1 - - [09/Nov/2023 16:06:50] "POST /predict HTTP/1.1" 200 -
INFO:werkzeug:127.0.0.1 - - [09/Nov/2023 16:08:53] "GET / HTTP/1.1" 200 -
INFO:werkzeug:127.0.0.1 - - [09/Nov/2023 16:08:53] "[36mGET /static/css/main.css HTTP/1.1[0m" 304 -
INFO:werkzeug:127.0.0.1 - - [09/Nov/2023 16:08:53] "[33mGET /path_to_facebook_icon.png HTTP/1.1[0m" 404 -
INFO:werkzeug:127.0.0.1 - - [09/Nov/2023 16:08:53] "[33mGET /path_to_twitter_icon.png HTTP/1.1[0m" 404 -
INFO:werkzeug:127.0.0.1 - - [09/Nov/2023 16:08:53] "[33mGET /path_to_instagram_icon.png HTTP/1.1[0m" 404 -
INFO:werkzeug:127.0.0.1 - - [09/Nov/2023 16:08:53] "GET /static/js/main.js HTTP/1.1" 200 -
ERROR:root:Error during prediction: in user code:

    File "C:\Users\Karthikeya\AppData\Local\Programs\Python\Python310\lib\site-packages\keras\src\engine\training.py", line 2416, in predict_function  *
        return step_function(self, iterator)
    File "C:\Users\Karthikeya\AppData\Local\Programs\Python\Python310\lib\site-packages\keras\src\engine\training.py", line 2401, in step_function  **
        outputs = model.distribute_strategy.run(run_step, args=(data,))
    File "C:\Users\Karthikeya\AppData\Local\Programs\Python\Python310\lib\site-packages\keras\src\engine\training.py", line 2389, in run_step  **
        outputs = model.predict_step(data)
    File "C:\Users\Karthikeya\AppData\Local\Programs\Python\Python310\lib\site-packages\keras\src\engine\training.py", line 2357, in predict_step
        return self(x, training=False)
    File "C:\Users\Karthikeya\AppData\Local\Programs\Python\Python310\lib\site-packages\keras\src\utils\traceback_utils.py", line 70, in error_handler
        raise e.with_traceback(filtered_tb) from None
    File "C:\Users\Karthikeya\AppData\Local\Programs\Python\Python310\lib\site-packages\keras\src\engine\input_spec.py", line 298, in assert_input_compatibility
        raise ValueError(

    ValueError: Input 0 of layer "model_2" is incompatible with the layer: expected shape=(None, 224, 224, 3), found shape=(None, 64, 64, 3)

ERROR:root:Error in prediction route: in user code:

    File "C:\Users\Karthikeya\AppData\Local\Programs\Python\Python310\lib\site-packages\keras\src\engine\training.py", line 2416, in predict_function  *
        return step_function(self, iterator)
    File "C:\Users\Karthikeya\AppData\Local\Programs\Python\Python310\lib\site-packages\keras\src\engine\training.py", line 2401, in step_function  **
        outputs = model.distribute_strategy.run(run_step, args=(data,))
    File "C:\Users\Karthikeya\AppData\Local\Programs\Python\Python310\lib\site-packages\keras\src\engine\training.py", line 2389, in run_step  **
        outputs = model.predict_step(data)
    File "C:\Users\Karthikeya\AppData\Local\Programs\Python\Python310\lib\site-packages\keras\src\engine\training.py", line 2357, in predict_step
        return self(x, training=False)
    File "C:\Users\Karthikeya\AppData\Local\Programs\Python\Python310\lib\site-packages\keras\src\utils\traceback_utils.py", line 70, in error_handler
        raise e.with_traceback(filtered_tb) from None
    File "C:\Users\Karthikeya\AppData\Local\Programs\Python\Python310\lib\site-packages\keras\src\engine\input_spec.py", line 298, in assert_input_compatibility
        raise ValueError(

    ValueError: Input 0 of layer "model_2" is incompatible with the layer: expected shape=(None, 224, 224, 3), found shape=(None, 64, 64, 3)

INFO:werkzeug:127.0.0.1 - - [09/Nov/2023 16:08:59] "POST /predict HTTP/1.1" 200 -
INFO:werkzeug:127.0.0.1 - - [09/Nov/2023 16:09:42] "GET / HTTP/1.1" 200 -
INFO:werkzeug:127.0.0.1 - - [09/Nov/2023 16:09:42] "[33mGET /path_to_facebook_icon.png HTTP/1.1[0m" 404 -
INFO:werkzeug:127.0.0.1 - - [09/Nov/2023 16:09:42] "[33mGET /path_to_twitter_icon.png HTTP/1.1[0m" 404 -
INFO:werkzeug:127.0.0.1 - - [09/Nov/2023 16:09:42] "[36mGET /static/css/main.css HTTP/1.1[0m" 304 -
INFO:werkzeug:127.0.0.1 - - [09/Nov/2023 16:09:42] "[33mGET /path_to_instagram_icon.png HTTP/1.1[0m" 404 -
INFO:werkzeug:127.0.0.1 - - [09/Nov/2023 16:09:42] "GET /static/js/main.js HTTP/1.1" 200 -
INFO:werkzeug:127.0.0.1 - - [09/Nov/2023 16:12:25] "GET / HTTP/1.1" 200 -
INFO:werkzeug:127.0.0.1 - - [09/Nov/2023 16:12:25] "[33mGET /path_to_facebook_icon.png HTTP/1.1[0m" 404 -
INFO:werkzeug:127.0.0.1 - - [09/Nov/2023 16:12:25] "[36mGET /static/css/main.css HTTP/1.1[0m" 304 -
INFO:werkzeug:127.0.0.1 - - [09/Nov/2023 16:12:25] "[33mGET /path_to_twitter_icon.png HTTP/1.1[0m" 404 -
INFO:werkzeug:127.0.0.1 - - [09/Nov/2023 16:12:25] "[33mGET /path_to_instagram_icon.png HTTP/1.1[0m" 404 -
INFO:werkzeug:127.0.0.1 - - [09/Nov/2023 16:12:25] "[36mGET /static/js/main.js HTTP/1.1[0m" 304 -
DEBUG:PIL.Image:Importing BlpImagePlugin
DEBUG:PIL.Image:Importing BmpImagePlugin
DEBUG:PIL.Image:Importing BufrStubImagePlugin
DEBUG:PIL.Image:Importing CurImagePlugin
DEBUG:PIL.Image:Importing DcxImagePlugin
DEBUG:PIL.Image:Importing DdsImagePlugin
DEBUG:PIL.Image:Importing EpsImagePlugin
DEBUG:PIL.Image:Importing FitsImagePlugin
DEBUG:PIL.Image:Importing FliImagePlugin
DEBUG:PIL.Image:Importing FpxImagePlugin
DEBUG:PIL.Image:Image: failed to import FpxImagePlugin: No module named 'olefile'
DEBUG:PIL.Image:Importing FtexImagePlugin
DEBUG:PIL.Image:Importing GbrImagePlugin
DEBUG:PIL.Image:Importing GifImagePlugin
DEBUG:PIL.Image:Importing GribStubImagePlugin
DEBUG:PIL.Image:Importing Hdf5StubImagePlugin
DEBUG:PIL.Image:Importing IcnsImagePlugin
DEBUG:PIL.Image:Importing IcoImagePlugin
DEBUG:PIL.Image:Importing ImImagePlugin
DEBUG:PIL.Image:Importing ImtImagePlugin
DEBUG:PIL.Image:Importing IptcImagePlugin
DEBUG:PIL.Image:Importing JpegImagePlugin
DEBUG:PIL.Image:Importing Jpeg2KImagePlugin
DEBUG:PIL.Image:Importing McIdasImagePlugin
DEBUG:PIL.Image:Importing MicImagePlugin
DEBUG:PIL.Image:Image: failed to import MicImagePlugin: No module named 'olefile'
DEBUG:PIL.Image:Importing MpegImagePlugin
DEBUG:PIL.Image:Importing MpoImagePlugin
DEBUG:PIL.Image:Importing MspImagePlugin
DEBUG:PIL.Image:Importing PalmImagePlugin
DEBUG:PIL.Image:Importing PcdImagePlugin
DEBUG:PIL.Image:Importing PcxImagePlugin
DEBUG:PIL.Image:Importing PdfImagePlugin
DEBUG:PIL.Image:Importing PixarImagePlugin
DEBUG:PIL.Image:Importing PngImagePlugin
DEBUG:PIL.Image:Importing PpmImagePlugin
DEBUG:PIL.Image:Importing PsdImagePlugin
DEBUG:PIL.Image:Importing QoiImagePlugin
DEBUG:PIL.Image:Importing SgiImagePlugin
DEBUG:PIL.Image:Importing SpiderImagePlugin
DEBUG:PIL.Image:Importing SunImagePlugin
DEBUG:PIL.Image:Importing TgaImagePlugin
DEBUG:PIL.Image:Importing TiffImagePlugin
DEBUG:PIL.Image:Importing WebPImagePlugin
ERROR:root:Error during prediction: in user code:

    File "C:\Users\Karthikeya\AppData\Local\Programs\Python\Python310\lib\site-packages\keras\src\engine\training.py", line 2416, in predict_function  *
        return step_function(self, iterator)
    File "C:\Users\Karthikeya\AppData\Local\Programs\Python\Python310\lib\site-packages\keras\src\engine\training.py", line 2401, in step_function  **
        outputs = model.distribute_strategy.run(run_step, args=(data,))
    File "C:\Users\Karthikeya\AppData\Local\Programs\Python\Python310\lib\site-packages\keras\src\engine\training.py", line 2389, in run_step  **
        outputs = model.predict_step(data)
    File "C:\Users\Karthikeya\AppData\Local\Programs\Python\Python310\lib\site-packages\keras\src\engine\training.py", line 2357, in predict_step
        return self(x, training=False)
    File "C:\Users\Karthikeya\AppData\Local\Programs\Python\Python310\lib\site-packages\keras\src\utils\traceback_utils.py", line 70, in error_handler
        raise e.with_traceback(filtered_tb) from None
    File "C:\Users\Karthikeya\AppData\Local\Programs\Python\Python310\lib\site-packages\keras\src\engine\input_spec.py", line 298, in assert_input_compatibility
        raise ValueError(

    ValueError: Input 0 of layer "model_2" is incompatible with the layer: expected shape=(None, 224, 224, 3), found shape=(None, 64, 64, 3)

ERROR:root:Error in prediction route: in user code:

    File "C:\Users\Karthikeya\AppData\Local\Programs\Python\Python310\lib\site-packages\keras\src\engine\training.py", line 2416, in predict_function  *
        return step_function(self, iterator)
    File "C:\Users\Karthikeya\AppData\Local\Programs\Python\Python310\lib\site-packages\keras\src\engine\training.py", line 2401, in step_function  **
        outputs = model.distribute_strategy.run(run_step, args=(data,))
    File "C:\Users\Karthikeya\AppData\Local\Programs\Python\Python310\lib\site-packages\keras\src\engine\training.py", line 2389, in run_step  **
        outputs = model.predict_step(data)
    File "C:\Users\Karthikeya\AppData\Local\Programs\Python\Python310\lib\site-packages\keras\src\engine\training.py", line 2357, in predict_step
        return self(x, training=False)
    File "C:\Users\Karthikeya\AppData\Local\Programs\Python\Python310\lib\site-packages\keras\src\utils\traceback_utils.py", line 70, in error_handler
        raise e.with_traceback(filtered_tb) from None
    File "C:\Users\Karthikeya\AppData\Local\Programs\Python\Python310\lib\site-packages\keras\src\engine\input_spec.py", line 298, in assert_input_compatibility
        raise ValueError(

    ValueError: Input 0 of layer "model_2" is incompatible with the layer: expected shape=(None, 224, 224, 3), found shape=(None, 64, 64, 3)

INFO:werkzeug:127.0.0.1 - - [09/Nov/2023 16:12:32] "POST /predict HTTP/1.1" 200 -
DEBUG:PIL.Image:Importing WmfImagePlugin
DEBUG:PIL.Image:Importing XbmImagePlugin
DEBUG:PIL.Image:Importing XpmImagePlugin
DEBUG:PIL.Image:Importing XVThumbImagePlugin
ERROR:root:Error during prediction: cannot identify image file 'temp_image.jpg'
ERROR:root:Error in prediction route: cannot identify image file 'temp_image.jpg'
INFO:werkzeug:127.0.0.1 - - [09/Nov/2023 16:12:33] "POST /predict HTTP/1.1" 200 -
INFO:werkzeug:127.0.0.1 - - [09/Nov/2023 16:13:46] "GET / HTTP/1.1" 200 -
INFO:werkzeug:127.0.0.1 - - [09/Nov/2023 16:13:46] "[33mGET /path_to_facebook_icon.png HTTP/1.1[0m" 404 -
INFO:werkzeug:127.0.0.1 - - [09/Nov/2023 16:13:46] "[33mGET /path_to_twitter_icon.png HTTP/1.1[0m" 404 -
INFO:werkzeug:127.0.0.1 - - [09/Nov/2023 16:13:46] "[36mGET /static/css/main.css HTTP/1.1[0m" 304 -
INFO:werkzeug:127.0.0.1 - - [09/Nov/2023 16:13:46] "[33mGET /path_to_instagram_icon.png HTTP/1.1[0m" 404 -
INFO:werkzeug:127.0.0.1 - - [09/Nov/2023 16:13:46] "[36mGET /static/js/main.js HTTP/1.1[0m" 304 -
ERROR:root:Error during prediction: in user code:

    File "C:\Users\Karthikeya\AppData\Local\Programs\Python\Python310\lib\site-packages\keras\src\engine\training.py", line 2416, in predict_function  *
        return step_function(self, iterator)
    File "C:\Users\Karthikeya\AppData\Local\Programs\Python\Python310\lib\site-packages\keras\src\engine\training.py", line 2401, in step_function  **
        outputs = model.distribute_strategy.run(run_step, args=(data,))
    File "C:\Users\Karthikeya\AppData\Local\Programs\Python\Python310\lib\site-packages\keras\src\engine\training.py", line 2389, in run_step  **
        outputs = model.predict_step(data)
    File "C:\Users\Karthikeya\AppData\Local\Programs\Python\Python310\lib\site-packages\keras\src\engine\training.py", line 2357, in predict_step
        return self(x, training=False)
    File "C:\Users\Karthikeya\AppData\Local\Programs\Python\Python310\lib\site-packages\keras\src\utils\traceback_utils.py", line 70, in error_handler
        raise e.with_traceback(filtered_tb) from None
    File "C:\Users\Karthikeya\AppData\Local\Programs\Python\Python310\lib\site-packages\keras\src\engine\input_spec.py", line 298, in assert_input_compatibility
        raise ValueError(

    ValueError: Input 0 of layer "model_2" is incompatible with the layer: expected shape=(None, 224, 224, 3), found shape=(None, 64, 64, 3)

ERROR:root:Error in prediction route: in user code:

    File "C:\Users\Karthikeya\AppData\Local\Programs\Python\Python310\lib\site-packages\keras\src\engine\training.py", line 2416, in predict_function  *
        return step_function(self, iterator)
    File "C:\Users\Karthikeya\AppData\Local\Programs\Python\Python310\lib\site-packages\keras\src\engine\training.py", line 2401, in step_function  **
        outputs = model.distribute_strategy.run(run_step, args=(data,))
    File "C:\Users\Karthikeya\AppData\Local\Programs\Python\Python310\lib\site-packages\keras\src\engine\training.py", line 2389, in run_step  **
        outputs = model.predict_step(data)
    File "C:\Users\Karthikeya\AppData\Local\Programs\Python\Python310\lib\site-packages\keras\src\engine\training.py", line 2357, in predict_step
        return self(x, training=False)
    File "C:\Users\Karthikeya\AppData\Local\Programs\Python\Python310\lib\site-packages\keras\src\utils\traceback_utils.py", line 70, in error_handler
        raise e.with_traceback(filtered_tb) from None
    File "C:\Users\Karthikeya\AppData\Local\Programs\Python\Python310\lib\site-packages\keras\src\engine\input_spec.py", line 298, in assert_input_compatibility
        raise ValueError(

    ValueError: Input 0 of layer "model_2" is incompatible with the layer: expected shape=(None, 224, 224, 3), found shape=(None, 64, 64, 3)

INFO:werkzeug:127.0.0.1 - - [09/Nov/2023 16:13:52] "POST /predict HTTP/1.1" 200 -
INFO:werkzeug:127.0.0.1 - - [09/Nov/2023 16:14:07] "GET / HTTP/1.1" 200 -
INFO:werkzeug:127.0.0.1 - - [09/Nov/2023 16:14:07] "[36mGET /static/css/main.css HTTP/1.1[0m" 304 -
INFO:werkzeug:127.0.0.1 - - [09/Nov/2023 16:14:07] "[33mGET /path_to_facebook_icon.png HTTP/1.1[0m" 404 -
INFO:werkzeug:127.0.0.1 - - [09/Nov/2023 16:14:07] "[33mGET /path_to_twitter_icon.png HTTP/1.1[0m" 404 -
INFO:werkzeug:127.0.0.1 - - [09/Nov/2023 16:14:07] "[33mGET /path_to_instagram_icon.png HTTP/1.1[0m" 404 -
INFO:werkzeug:127.0.0.1 - - [09/Nov/2023 16:14:07] "[36mGET /static/js/main.js HTTP/1.1[0m" 304 -
ERROR:root:Error during prediction: in user code:

    File "C:\Users\Karthikeya\AppData\Local\Programs\Python\Python310\lib\site-packages\keras\src\engine\training.py", line 2416, in predict_function  *
        return step_function(self, iterator)
    File "C:\Users\Karthikeya\AppData\Local\Programs\Python\Python310\lib\site-packages\keras\src\engine\training.py", line 2401, in step_function  **
        outputs = model.distribute_strategy.run(run_step, args=(data,))
    File "C:\Users\Karthikeya\AppData\Local\Programs\Python\Python310\lib\site-packages\keras\src\engine\training.py", line 2389, in run_step  **
        outputs = model.predict_step(data)
    File "C:\Users\Karthikeya\AppData\Local\Programs\Python\Python310\lib\site-packages\keras\src\engine\training.py", line 2357, in predict_step
        return self(x, training=False)
    File "C:\Users\Karthikeya\AppData\Local\Programs\Python\Python310\lib\site-packages\keras\src\utils\traceback_utils.py", line 70, in error_handler
        raise e.with_traceback(filtered_tb) from None
    File "C:\Users\Karthikeya\AppData\Local\Programs\Python\Python310\lib\site-packages\keras\src\engine\input_spec.py", line 298, in assert_input_compatibility
        raise ValueError(

    ValueError: Input 0 of layer "model_2" is incompatible with the layer: expected shape=(None, 224, 224, 3), found shape=(None, 64, 64, 3)

ERROR:root:Error in prediction route: in user code:

    File "C:\Users\Karthikeya\AppData\Local\Programs\Python\Python310\lib\site-packages\keras\src\engine\training.py", line 2416, in predict_function  *
        return step_function(self, iterator)
    File "C:\Users\Karthikeya\AppData\Local\Programs\Python\Python310\lib\site-packages\keras\src\engine\training.py", line 2401, in step_function  **
        outputs = model.distribute_strategy.run(run_step, args=(data,))
    File "C:\Users\Karthikeya\AppData\Local\Programs\Python\Python310\lib\site-packages\keras\src\engine\training.py", line 2389, in run_step  **
        outputs = model.predict_step(data)
    File "C:\Users\Karthikeya\AppData\Local\Programs\Python\Python310\lib\site-packages\keras\src\engine\training.py", line 2357, in predict_step
        return self(x, training=False)
    File "C:\Users\Karthikeya\AppData\Local\Programs\Python\Python310\lib\site-packages\keras\src\utils\traceback_utils.py", line 70, in error_handler
        raise e.with_traceback(filtered_tb) from None
    File "C:\Users\Karthikeya\AppData\Local\Programs\Python\Python310\lib\site-packages\keras\src\engine\input_spec.py", line 298, in assert_input_compatibility
        raise ValueError(

    ValueError: Input 0 of layer "model_2" is incompatible with the layer: expected shape=(None, 224, 224, 3), found shape=(None, 64, 64, 3)

INFO:werkzeug:127.0.0.1 - - [09/Nov/2023 16:14:14] "POST /predict HTTP/1.1" 200 -
ERROR:root:Error during prediction: in user code:

    File "C:\Users\Karthikeya\AppData\Local\Programs\Python\Python310\lib\site-packages\keras\src\engine\training.py", line 2416, in predict_function  *
        return step_function(self, iterator)
    File "C:\Users\Karthikeya\AppData\Local\Programs\Python\Python310\lib\site-packages\keras\src\engine\training.py", line 2401, in step_function  **
        outputs = model.distribute_strategy.run(run_step, args=(data,))
    File "C:\Users\Karthikeya\AppData\Local\Programs\Python\Python310\lib\site-packages\keras\src\engine\training.py", line 2389, in run_step  **
        outputs = model.predict_step(data)
    File "C:\Users\Karthikeya\AppData\Local\Programs\Python\Python310\lib\site-packages\keras\src\engine\training.py", line 2357, in predict_step
        return self(x, training=False)
    File "C:\Users\Karthikeya\AppData\Local\Programs\Python\Python310\lib\site-packages\keras\src\utils\traceback_utils.py", line 70, in error_handler
        raise e.with_traceback(filtered_tb) from None
    File "C:\Users\Karthikeya\AppData\Local\Programs\Python\Python310\lib\site-packages\keras\src\engine\input_spec.py", line 298, in assert_input_compatibility
        raise ValueError(

    ValueError: Input 0 of layer "model_2" is incompatible with the layer: expected shape=(None, 224, 224, 3), found shape=(None, 64, 64, 3)

ERROR:root:Error in prediction route: in user code:

    File "C:\Users\Karthikeya\AppData\Local\Programs\Python\Python310\lib\site-packages\keras\src\engine\training.py", line 2416, in predict_function  *
        return step_function(self, iterator)
    File "C:\Users\Karthikeya\AppData\Local\Programs\Python\Python310\lib\site-packages\keras\src\engine\training.py", line 2401, in step_function  **
        outputs = model.distribute_strategy.run(run_step, args=(data,))
    File "C:\Users\Karthikeya\AppData\Local\Programs\Python\Python310\lib\site-packages\keras\src\engine\training.py", line 2389, in run_step  **
        outputs = model.predict_step(data)
    File "C:\Users\Karthikeya\AppData\Local\Programs\Python\Python310\lib\site-packages\keras\src\engine\training.py", line 2357, in predict_step
        return self(x, training=False)
    File "C:\Users\Karthikeya\AppData\Local\Programs\Python\Python310\lib\site-packages\keras\src\utils\traceback_utils.py", line 70, in error_handler
        raise e.with_traceback(filtered_tb) from None
    File "C:\Users\Karthikeya\AppData\Local\Programs\Python\Python310\lib\site-packages\keras\src\engine\input_spec.py", line 298, in assert_input_compatibility
        raise ValueError(

    ValueError: Input 0 of layer "model_2" is incompatible with the layer: expected shape=(None, 224, 224, 3), found shape=(None, 64, 64, 3)

INFO:werkzeug:127.0.0.1 - - [09/Nov/2023 16:14:14] "POST /predict HTTP/1.1" 200 -
INFO:werkzeug:127.0.0.1 - - [09/Nov/2023 16:15:14] "GET / HTTP/1.1" 200 -
INFO:werkzeug:127.0.0.1 - - [09/Nov/2023 16:15:14] "[36mGET /static/css/main.css HTTP/1.1[0m" 304 -
INFO:werkzeug:127.0.0.1 - - [09/Nov/2023 16:15:14] "[33mGET /path_to_facebook_icon.png HTTP/1.1[0m" 404 -
INFO:werkzeug:127.0.0.1 - - [09/Nov/2023 16:15:14] "[33mGET /path_to_twitter_icon.png HTTP/1.1[0m" 404 -
INFO:werkzeug:127.0.0.1 - - [09/Nov/2023 16:15:14] "[33mGET /path_to_instagram_icon.png HTTP/1.1[0m" 404 -
INFO:werkzeug:127.0.0.1 - - [09/Nov/2023 16:15:14] "[36mGET /static/js/main.js HTTP/1.1[0m" 304 -
INFO:werkzeug:127.0.0.1 - - [09/Nov/2023 16:16:17] "GET / HTTP/1.1" 200 -
INFO:werkzeug:127.0.0.1 - - [09/Nov/2023 16:16:17] "[36mGET /static/css/main.css HTTP/1.1[0m" 304 -
INFO:werkzeug:127.0.0.1 - - [09/Nov/2023 16:16:17] "[33mGET /path_to_facebook_icon.png HTTP/1.1[0m" 404 -
INFO:werkzeug:127.0.0.1 - - [09/Nov/2023 16:16:17] "[33mGET /path_to_twitter_icon.png HTTP/1.1[0m" 404 -
INFO:werkzeug:127.0.0.1 - - [09/Nov/2023 16:16:17] "[33mGET /path_to_instagram_icon.png HTTP/1.1[0m" 404 -
INFO:werkzeug:127.0.0.1 - - [09/Nov/2023 16:16:17] "[36mGET /static/js/main.js HTTP/1.1[0m" 304 -
ERROR:root:Error during prediction: in user code:

    File "C:\Users\Karthikeya\AppData\Local\Programs\Python\Python310\lib\site-packages\keras\src\engine\training.py", line 2416, in predict_function  *
        return step_function(self, iterator)
    File "C:\Users\Karthikeya\AppData\Local\Programs\Python\Python310\lib\site-packages\keras\src\engine\training.py", line 2401, in step_function  **
        outputs = model.distribute_strategy.run(run_step, args=(data,))
    File "C:\Users\Karthikeya\AppData\Local\Programs\Python\Python310\lib\site-packages\keras\src\engine\training.py", line 2389, in run_step  **
        outputs = model.predict_step(data)
    File "C:\Users\Karthikeya\AppData\Local\Programs\Python\Python310\lib\site-packages\keras\src\engine\training.py", line 2357, in predict_step
        return self(x, training=False)
    File "C:\Users\Karthikeya\AppData\Local\Programs\Python\Python310\lib\site-packages\keras\src\utils\traceback_utils.py", line 70, in error_handler
        raise e.with_traceback(filtered_tb) from None
    File "C:\Users\Karthikeya\AppData\Local\Programs\Python\Python310\lib\site-packages\keras\src\engine\input_spec.py", line 298, in assert_input_compatibility
        raise ValueError(

    ValueError: Input 0 of layer "model_2" is incompatible with the layer: expected shape=(None, 224, 224, 3), found shape=(None, 64, 64, 3)

ERROR:root:Error in prediction route: in user code:

    File "C:\Users\Karthikeya\AppData\Local\Programs\Python\Python310\lib\site-packages\keras\src\engine\training.py", line 2416, in predict_function  *
        return step_function(self, iterator)
    File "C:\Users\Karthikeya\AppData\Local\Programs\Python\Python310\lib\site-packages\keras\src\engine\training.py", line 2401, in step_function  **
        outputs = model.distribute_strategy.run(run_step, args=(data,))
    File "C:\Users\Karthikeya\AppData\Local\Programs\Python\Python310\lib\site-packages\keras\src\engine\training.py", line 2389, in run_step  **
        outputs = model.predict_step(data)
    File "C:\Users\Karthikeya\AppData\Local\Programs\Python\Python310\lib\site-packages\keras\src\engine\training.py", line 2357, in predict_step
        return self(x, training=False)
    File "C:\Users\Karthikeya\AppData\Local\Programs\Python\Python310\lib\site-packages\keras\src\utils\traceback_utils.py", line 70, in error_handler
        raise e.with_traceback(filtered_tb) from None
    File "C:\Users\Karthikeya\AppData\Local\Programs\Python\Python310\lib\site-packages\keras\src\engine\input_spec.py", line 298, in assert_input_compatibility
        raise ValueError(

    ValueError: Input 0 of layer "model_2" is incompatible with the layer: expected shape=(None, 224, 224, 3), found shape=(None, 64, 64, 3)

INFO:werkzeug:127.0.0.1 - - [09/Nov/2023 16:16:23] "POST /predict HTTP/1.1" 200 -
ERROR:root:Error during prediction: in user code:

    File "C:\Users\Karthikeya\AppData\Local\Programs\Python\Python310\lib\site-packages\keras\src\engine\training.py", line 2416, in predict_function  *
        return step_function(self, iterator)
    File "C:\Users\Karthikeya\AppData\Local\Programs\Python\Python310\lib\site-packages\keras\src\engine\training.py", line 2401, in step_function  **
        outputs = model.distribute_strategy.run(run_step, args=(data,))
    File "C:\Users\Karthikeya\AppData\Local\Programs\Python\Python310\lib\site-packages\keras\src\engine\training.py", line 2389, in run_step  **
        outputs = model.predict_step(data)
    File "C:\Users\Karthikeya\AppData\Local\Programs\Python\Python310\lib\site-packages\keras\src\engine\training.py", line 2357, in predict_step
        return self(x, training=False)
    File "C:\Users\Karthikeya\AppData\Local\Programs\Python\Python310\lib\site-packages\keras\src\utils\traceback_utils.py", line 70, in error_handler
        raise e.with_traceback(filtered_tb) from None
    File "C:\Users\Karthikeya\AppData\Local\Programs\Python\Python310\lib\site-packages\keras\src\engine\input_spec.py", line 298, in assert_input_compatibility
        raise ValueError(

    ValueError: Input 0 of layer "model_2" is incompatible with the layer: expected shape=(None, 224, 224, 3), found shape=(None, 64, 64, 3)

ERROR:root:Error in prediction route: in user code:

    File "C:\Users\Karthikeya\AppData\Local\Programs\Python\Python310\lib\site-packages\keras\src\engine\training.py", line 2416, in predict_function  *
        return step_function(self, iterator)
    File "C:\Users\Karthikeya\AppData\Local\Programs\Python\Python310\lib\site-packages\keras\src\engine\training.py", line 2401, in step_function  **
        outputs = model.distribute_strategy.run(run_step, args=(data,))
    File "C:\Users\Karthikeya\AppData\Local\Programs\Python\Python310\lib\site-packages\keras\src\engine\training.py", line 2389, in run_step  **
        outputs = model.predict_step(data)
    File "C:\Users\Karthikeya\AppData\Local\Programs\Python\Python310\lib\site-packages\keras\src\engine\training.py", line 2357, in predict_step
        return self(x, training=False)
    File "C:\Users\Karthikeya\AppData\Local\Programs\Python\Python310\lib\site-packages\keras\src\utils\traceback_utils.py", line 70, in error_handler
        raise e.with_traceback(filtered_tb) from None
    File "C:\Users\Karthikeya\AppData\Local\Programs\Python\Python310\lib\site-packages\keras\src\engine\input_spec.py", line 298, in assert_input_compatibility
        raise ValueError(

    ValueError: Input 0 of layer "model_2" is incompatible with the layer: expected shape=(None, 224, 224, 3), found shape=(None, 64, 64, 3)

INFO:werkzeug:127.0.0.1 - - [09/Nov/2023 16:16:23] "POST /predict HTTP/1.1" 200 -
INFO:werkzeug:127.0.0.1 - - [09/Nov/2023 16:17:30] "GET / HTTP/1.1" 200 -
INFO:werkzeug:127.0.0.1 - - [09/Nov/2023 16:17:30] "[36mGET /static/css/main.css HTTP/1.1[0m" 304 -
INFO:werkzeug:127.0.0.1 - - [09/Nov/2023 16:17:30] "[33mGET /path_to_facebook_icon.png HTTP/1.1[0m" 404 -
INFO:werkzeug:127.0.0.1 - - [09/Nov/2023 16:17:30] "[33mGET /path_to_twitter_icon.png HTTP/1.1[0m" 404 -
INFO:werkzeug:127.0.0.1 - - [09/Nov/2023 16:17:30] "[33mGET /path_to_instagram_icon.png HTTP/1.1[0m" 404 -
INFO:werkzeug:127.0.0.1 - - [09/Nov/2023 16:17:30] "[36mGET /static/js/main.js HTTP/1.1[0m" 304 -
ERROR:root:Error during prediction: in user code:

    File "C:\Users\Karthikeya\AppData\Local\Programs\Python\Python310\lib\site-packages\keras\src\engine\training.py", line 2416, in predict_function  *
        return step_function(self, iterator)
    File "C:\Users\Karthikeya\AppData\Local\Programs\Python\Python310\lib\site-packages\keras\src\engine\training.py", line 2401, in step_function  **
        outputs = model.distribute_strategy.run(run_step, args=(data,))
    File "C:\Users\Karthikeya\AppData\Local\Programs\Python\Python310\lib\site-packages\keras\src\engine\training.py", line 2389, in run_step  **
        outputs = model.predict_step(data)
    File "C:\Users\Karthikeya\AppData\Local\Programs\Python\Python310\lib\site-packages\keras\src\engine\training.py", line 2357, in predict_step
        return self(x, training=False)
    File "C:\Users\Karthikeya\AppData\Local\Programs\Python\Python310\lib\site-packages\keras\src\utils\traceback_utils.py", line 70, in error_handler
        raise e.with_traceback(filtered_tb) from None
    File "C:\Users\Karthikeya\AppData\Local\Programs\Python\Python310\lib\site-packages\keras\src\engine\input_spec.py", line 298, in assert_input_compatibility
        raise ValueError(

    ValueError: Input 0 of layer "model_2" is incompatible with the layer: expected shape=(None, 224, 224, 3), found shape=(None, 64, 64, 3)

ERROR:root:Error in prediction route: in user code:

    File "C:\Users\Karthikeya\AppData\Local\Programs\Python\Python310\lib\site-packages\keras\src\engine\training.py", line 2416, in predict_function  *
        return step_function(self, iterator)
    File "C:\Users\Karthikeya\AppData\Local\Programs\Python\Python310\lib\site-packages\keras\src\engine\training.py", line 2401, in step_function  **
        outputs = model.distribute_strategy.run(run_step, args=(data,))
    File "C:\Users\Karthikeya\AppData\Local\Programs\Python\Python310\lib\site-packages\keras\src\engine\training.py", line 2389, in run_step  **
        outputs = model.predict_step(data)
    File "C:\Users\Karthikeya\AppData\Local\Programs\Python\Python310\lib\site-packages\keras\src\engine\training.py", line 2357, in predict_step
        return self(x, training=False)
    File "C:\Users\Karthikeya\AppData\Local\Programs\Python\Python310\lib\site-packages\keras\src\utils\traceback_utils.py", line 70, in error_handler
        raise e.with_traceback(filtered_tb) from None
    File "C:\Users\Karthikeya\AppData\Local\Programs\Python\Python310\lib\site-packages\keras\src\engine\input_spec.py", line 298, in assert_input_compatibility
        raise ValueError(

    ValueError: Input 0 of layer "model_2" is incompatible with the layer: expected shape=(None, 224, 224, 3), found shape=(None, 64, 64, 3)

INFO:werkzeug:127.0.0.1 - - [09/Nov/2023 16:17:36] "POST /predict HTTP/1.1" 200 -
ERROR:root:Error during prediction: in user code:

    File "C:\Users\Karthikeya\AppData\Local\Programs\Python\Python310\lib\site-packages\keras\src\engine\training.py", line 2416, in predict_function  *
        return step_function(self, iterator)
    File "C:\Users\Karthikeya\AppData\Local\Programs\Python\Python310\lib\site-packages\keras\src\engine\training.py", line 2401, in step_function  **
        outputs = model.distribute_strategy.run(run_step, args=(data,))
    File "C:\Users\Karthikeya\AppData\Local\Programs\Python\Python310\lib\site-packages\keras\src\engine\training.py", line 2389, in run_step  **
        outputs = model.predict_step(data)
    File "C:\Users\Karthikeya\AppData\Local\Programs\Python\Python310\lib\site-packages\keras\src\engine\training.py", line 2357, in predict_step
        return self(x, training=False)
    File "C:\Users\Karthikeya\AppData\Local\Programs\Python\Python310\lib\site-packages\keras\src\utils\traceback_utils.py", line 70, in error_handler
        raise e.with_traceback(filtered_tb) from None
    File "C:\Users\Karthikeya\AppData\Local\Programs\Python\Python310\lib\site-packages\keras\src\engine\input_spec.py", line 298, in assert_input_compatibility
        raise ValueError(

    ValueError: Input 0 of layer "model_2" is incompatible with the layer: expected shape=(None, 224, 224, 3), found shape=(None, 64, 64, 3)

ERROR:root:Error in prediction route: in user code:

    File "C:\Users\Karthikeya\AppData\Local\Programs\Python\Python310\lib\site-packages\keras\src\engine\training.py", line 2416, in predict_function  *
        return step_function(self, iterator)
    File "C:\Users\Karthikeya\AppData\Local\Programs\Python\Python310\lib\site-packages\keras\src\engine\training.py", line 2401, in step_function  **
        outputs = model.distribute_strategy.run(run_step, args=(data,))
    File "C:\Users\Karthikeya\AppData\Local\Programs\Python\Python310\lib\site-packages\keras\src\engine\training.py", line 2389, in run_step  **
        outputs = model.predict_step(data)
    File "C:\Users\Karthikeya\AppData\Local\Programs\Python\Python310\lib\site-packages\keras\src\engine\training.py", line 2357, in predict_step
        return self(x, training=False)
    File "C:\Users\Karthikeya\AppData\Local\Programs\Python\Python310\lib\site-packages\keras\src\utils\traceback_utils.py", line 70, in error_handler
        raise e.with_traceback(filtered_tb) from None
    File "C:\Users\Karthikeya\AppData\Local\Programs\Python\Python310\lib\site-packages\keras\src\engine\input_spec.py", line 298, in assert_input_compatibility
        raise ValueError(

    ValueError: Input 0 of layer "model_2" is incompatible with the layer: expected shape=(None, 224, 224, 3), found shape=(None, 64, 64, 3)

INFO:werkzeug:127.0.0.1 - - [09/Nov/2023 16:17:36] "POST /predict HTTP/1.1" 200 -
INFO:werkzeug:127.0.0.1 - - [09/Nov/2023 16:17:38] "GET / HTTP/1.1" 200 -
INFO:werkzeug:127.0.0.1 - - [09/Nov/2023 16:17:38] "[33mGET /path_to_facebook_icon.png HTTP/1.1[0m" 404 -
INFO:werkzeug:127.0.0.1 - - [09/Nov/2023 16:17:38] "[36mGET /static/css/main.css HTTP/1.1[0m" 304 -
INFO:werkzeug:127.0.0.1 - - [09/Nov/2023 16:17:38] "[33mGET /path_to_twitter_icon.png HTTP/1.1[0m" 404 -
INFO:werkzeug:127.0.0.1 - - [09/Nov/2023 16:17:38] "[33mGET /path_to_instagram_icon.png HTTP/1.1[0m" 404 -
INFO:werkzeug:127.0.0.1 - - [09/Nov/2023 16:17:38] "[36mGET /static/js/main.js HTTP/1.1[0m" 304 -
ERROR:root:Error during prediction: cannot identify image file 'temp_image.jpg'
ERROR:root:Error in prediction route: cannot identify image file 'temp_image.jpg'
INFO:werkzeug:127.0.0.1 - - [09/Nov/2023 16:17:45] "POST /predict HTTP/1.1" 200 -
ERROR:root:Error during prediction: in user code:

    File "C:\Users\Karthikeya\AppData\Local\Programs\Python\Python310\lib\site-packages\keras\src\engine\training.py", line 2416, in predict_function  *
        return step_function(self, iterator)
    File "C:\Users\Karthikeya\AppData\Local\Programs\Python\Python310\lib\site-packages\keras\src\engine\training.py", line 2401, in step_function  **
        outputs = model.distribute_strategy.run(run_step, args=(data,))
    File "C:\Users\Karthikeya\AppData\Local\Programs\Python\Python310\lib\site-packages\keras\src\engine\training.py", line 2389, in run_step  **
        outputs = model.predict_step(data)
    File "C:\Users\Karthikeya\AppData\Local\Programs\Python\Python310\lib\site-packages\keras\src\engine\training.py", line 2357, in predict_step
        return self(x, training=False)
    File "C:\Users\Karthikeya\AppData\Local\Programs\Python\Python310\lib\site-packages\keras\src\utils\traceback_utils.py", line 70, in error_handler
        raise e.with_traceback(filtered_tb) from None
    File "C:\Users\Karthikeya\AppData\Local\Programs\Python\Python310\lib\site-packages\keras\src\engine\input_spec.py", line 298, in assert_input_compatibility
        raise ValueError(

    ValueError: Input 0 of layer "model_2" is incompatible with the layer: expected shape=(None, 224, 224, 3), found shape=(None, 64, 64, 3)

ERROR:root:Error in prediction route: in user code:

    File "C:\Users\Karthikeya\AppData\Local\Programs\Python\Python310\lib\site-packages\keras\src\engine\training.py", line 2416, in predict_function  *
        return step_function(self, iterator)
    File "C:\Users\Karthikeya\AppData\Local\Programs\Python\Python310\lib\site-packages\keras\src\engine\training.py", line 2401, in step_function  **
        outputs = model.distribute_strategy.run(run_step, args=(data,))
    File "C:\Users\Karthikeya\AppData\Local\Programs\Python\Python310\lib\site-packages\keras\src\engine\training.py", line 2389, in run_step  **
        outputs = model.predict_step(data)
    File "C:\Users\Karthikeya\AppData\Local\Programs\Python\Python310\lib\site-packages\keras\src\engine\training.py", line 2357, in predict_step
        return self(x, training=False)
    File "C:\Users\Karthikeya\AppData\Local\Programs\Python\Python310\lib\site-packages\keras\src\utils\traceback_utils.py", line 70, in error_handler
        raise e.with_traceback(filtered_tb) from None
    File "C:\Users\Karthikeya\AppData\Local\Programs\Python\Python310\lib\site-packages\keras\src\engine\input_spec.py", line 298, in assert_input_compatibility
        raise ValueError(

    ValueError: Input 0 of layer "model_2" is incompatible with the layer: expected shape=(None, 224, 224, 3), found shape=(None, 64, 64, 3)

INFO:werkzeug:127.0.0.1 - - [09/Nov/2023 16:17:45] "POST /predict HTTP/1.1" 200 -
INFO:werkzeug: * Detected change in 'c:\\Users\\Karthikeya\\PycharmProjects\\project_AI\\app.py', reloading
WARNING:werkzeug: * Debugger is active!
INFO:werkzeug: * Debugger PIN: 912-154-751
INFO:werkzeug:127.0.0.1 - - [09/Nov/2023 16:19:02] "GET / HTTP/1.1" 200 -
INFO:werkzeug:127.0.0.1 - - [09/Nov/2023 16:19:02] "[33mGET /path_to_facebook_icon.png HTTP/1.1[0m" 404 -
INFO:werkzeug:127.0.0.1 - - [09/Nov/2023 16:19:02] "[33mGET /path_to_twitter_icon.png HTTP/1.1[0m" 404 -
INFO:werkzeug:127.0.0.1 - - [09/Nov/2023 16:19:02] "[33mGET /path_to_instagram_icon.png HTTP/1.1[0m" 404 -
INFO:werkzeug:127.0.0.1 - - [09/Nov/2023 16:19:03] "[36mGET /static/css/main.css HTTP/1.1[0m" 304 -
INFO:werkzeug:127.0.0.1 - - [09/Nov/2023 16:19:03] "[36mGET /static/js/main.js HTTP/1.1[0m" 304 -
ERROR:root:Prediction error: in user code:

    File "C:\Users\Karthikeya\AppData\Local\Programs\Python\Python310\lib\site-packages\keras\src\engine\training.py", line 2416, in predict_function  *
        return step_function(self, iterator)
    File "C:\Users\Karthikeya\AppData\Local\Programs\Python\Python310\lib\site-packages\keras\src\engine\training.py", line 2401, in step_function  **
        outputs = model.distribute_strategy.run(run_step, args=(data,))
    File "C:\Users\Karthikeya\AppData\Local\Programs\Python\Python310\lib\site-packages\keras\src\engine\training.py", line 2389, in run_step  **
        outputs = model.predict_step(data)
    File "C:\Users\Karthikeya\AppData\Local\Programs\Python\Python310\lib\site-packages\keras\src\engine\training.py", line 2357, in predict_step
        return self(x, training=False)
    File "C:\Users\Karthikeya\AppData\Local\Programs\Python\Python310\lib\site-packages\keras\src\utils\traceback_utils.py", line 70, in error_handler
        raise e.with_traceback(filtered_tb) from None
    File "C:\Users\Karthikeya\AppData\Local\Programs\Python\Python310\lib\site-packages\keras\src\engine\input_spec.py", line 298, in assert_input_compatibility
        raise ValueError(

    ValueError: Input 0 of layer "model_2" is incompatible with the layer: expected shape=(None, 224, 224, 3), found shape=(None, 64, 64, 3)

INFO:werkzeug:127.0.0.1 - - [09/Nov/2023 16:19:09] "[35m[1mPOST /predict HTTP/1.1[0m" 500 -
ERROR:root:Prediction error: in user code:

    File "C:\Users\Karthikeya\AppData\Local\Programs\Python\Python310\lib\site-packages\keras\src\engine\training.py", line 2416, in predict_function  *
        return step_function(self, iterator)
    File "C:\Users\Karthikeya\AppData\Local\Programs\Python\Python310\lib\site-packages\keras\src\engine\training.py", line 2401, in step_function  **
        outputs = model.distribute_strategy.run(run_step, args=(data,))
    File "C:\Users\Karthikeya\AppData\Local\Programs\Python\Python310\lib\site-packages\keras\src\engine\training.py", line 2389, in run_step  **
        outputs = model.predict_step(data)
    File "C:\Users\Karthikeya\AppData\Local\Programs\Python\Python310\lib\site-packages\keras\src\engine\training.py", line 2357, in predict_step
        return self(x, training=False)
    File "C:\Users\Karthikeya\AppData\Local\Programs\Python\Python310\lib\site-packages\keras\src\utils\traceback_utils.py", line 70, in error_handler
        raise e.with_traceback(filtered_tb) from None
    File "C:\Users\Karthikeya\AppData\Local\Programs\Python\Python310\lib\site-packages\keras\src\engine\input_spec.py", line 298, in assert_input_compatibility
        raise ValueError(

    ValueError: Input 0 of layer "model_2" is incompatible with the layer: expected shape=(None, 224, 224, 3), found shape=(None, 64, 64, 3)

INFO:werkzeug:127.0.0.1 - - [09/Nov/2023 16:19:09] "[35m[1mPOST /predict HTTP/1.1[0m" 500 -
INFO:werkzeug: * Detected change in 'c:\\Users\\Karthikeya\\PycharmProjects\\project_AI\\app.py', reloading
WARNING:werkzeug: * Debugger is active!
INFO:werkzeug: * Debugger PIN: 912-154-751
INFO:werkzeug:127.0.0.1 - - [09/Nov/2023 16:20:39] "GET / HTTP/1.1" 200 -
INFO:werkzeug:127.0.0.1 - - [09/Nov/2023 16:20:39] "[33mGET /path_to_facebook_icon.png HTTP/1.1[0m" 404 -
INFO:werkzeug:127.0.0.1 - - [09/Nov/2023 16:20:39] "[33mGET /path_to_twitter_icon.png HTTP/1.1[0m" 404 -
INFO:werkzeug:127.0.0.1 - - [09/Nov/2023 16:20:39] "[33mGET /path_to_instagram_icon.png HTTP/1.1[0m" 404 -
INFO:werkzeug:127.0.0.1 - - [09/Nov/2023 16:20:39] "[36mGET /static/css/main.css HTTP/1.1[0m" 304 -
INFO:werkzeug:127.0.0.1 - - [09/Nov/2023 16:20:39] "[36mGET /static/js/main.js HTTP/1.1[0m" 304 -
ERROR:root:Prediction error: in user code:

    File "C:\Users\Karthikeya\AppData\Local\Programs\Python\Python310\lib\site-packages\keras\src\engine\training.py", line 2416, in predict_function  *
        return step_function(self, iterator)
    File "C:\Users\Karthikeya\AppData\Local\Programs\Python\Python310\lib\site-packages\keras\src\engine\training.py", line 2401, in step_function  **
        outputs = model.distribute_strategy.run(run_step, args=(data,))
    File "C:\Users\Karthikeya\AppData\Local\Programs\Python\Python310\lib\site-packages\keras\src\engine\training.py", line 2389, in run_step  **
        outputs = model.predict_step(data)
    File "C:\Users\Karthikeya\AppData\Local\Programs\Python\Python310\lib\site-packages\keras\src\engine\training.py", line 2357, in predict_step
        return self(x, training=False)
    File "C:\Users\Karthikeya\AppData\Local\Programs\Python\Python310\lib\site-packages\keras\src\utils\traceback_utils.py", line 70, in error_handler
        raise e.with_traceback(filtered_tb) from None
    File "C:\Users\Karthikeya\AppData\Local\Programs\Python\Python310\lib\site-packages\keras\src\engine\input_spec.py", line 298, in assert_input_compatibility
        raise ValueError(

    ValueError: Input 0 of layer "model_2" is incompatible with the layer: expected shape=(None, 224, 224, 3), found shape=(None, 64, 64, 3)

INFO:werkzeug:127.0.0.1 - - [09/Nov/2023 16:20:47] "[35m[1mPOST /predict HTTP/1.1[0m" 500 -
ERROR:root:Prediction error: in user code:

    File "C:\Users\Karthikeya\AppData\Local\Programs\Python\Python310\lib\site-packages\keras\src\engine\training.py", line 2416, in predict_function  *
        return step_function(self, iterator)
    File "C:\Users\Karthikeya\AppData\Local\Programs\Python\Python310\lib\site-packages\keras\src\engine\training.py", line 2401, in step_function  **
        outputs = model.distribute_strategy.run(run_step, args=(data,))
    File "C:\Users\Karthikeya\AppData\Local\Programs\Python\Python310\lib\site-packages\keras\src\engine\training.py", line 2389, in run_step  **
        outputs = model.predict_step(data)
    File "C:\Users\Karthikeya\AppData\Local\Programs\Python\Python310\lib\site-packages\keras\src\engine\training.py", line 2357, in predict_step
        return self(x, training=False)
    File "C:\Users\Karthikeya\AppData\Local\Programs\Python\Python310\lib\site-packages\keras\src\utils\traceback_utils.py", line 70, in error_handler
        raise e.with_traceback(filtered_tb) from None
    File "C:\Users\Karthikeya\AppData\Local\Programs\Python\Python310\lib\site-packages\keras\src\engine\input_spec.py", line 298, in assert_input_compatibility
        raise ValueError(

    ValueError: Input 0 of layer "model_2" is incompatible with the layer: expected shape=(None, 224, 224, 3), found shape=(None, 64, 64, 3)

INFO:werkzeug:127.0.0.1 - - [09/Nov/2023 16:20:47] "[35m[1mPOST /predict HTTP/1.1[0m" 500 -
INFO:werkzeug:127.0.0.1 - - [09/Nov/2023 16:22:02] "GET / HTTP/1.1" 200 -
INFO:werkzeug:127.0.0.1 - - [09/Nov/2023 16:22:02] "[36mGET /static/css/main.css HTTP/1.1[0m" 304 -
INFO:werkzeug:127.0.0.1 - - [09/Nov/2023 16:22:02] "[33mGET /path_to_facebook_icon.png HTTP/1.1[0m" 404 -
INFO:werkzeug:127.0.0.1 - - [09/Nov/2023 16:22:02] "[33mGET /path_to_twitter_icon.png HTTP/1.1[0m" 404 -
INFO:werkzeug:127.0.0.1 - - [09/Nov/2023 16:22:02] "[33mGET /path_to_instagram_icon.png HTTP/1.1[0m" 404 -
INFO:werkzeug:127.0.0.1 - - [09/Nov/2023 16:22:02] "[36mGET /static/js/main.js HTTP/1.1[0m" 304 -
INFO:werkzeug:127.0.0.1 - - [09/Nov/2023 16:22:18] "GET / HTTP/1.1" 200 -
INFO:werkzeug:127.0.0.1 - - [09/Nov/2023 16:22:18] "[33mGET /path_to_facebook_icon.png HTTP/1.1[0m" 404 -
INFO:werkzeug:127.0.0.1 - - [09/Nov/2023 16:22:18] "[36mGET /static/css/main.css HTTP/1.1[0m" 304 -
INFO:werkzeug:127.0.0.1 - - [09/Nov/2023 16:22:18] "[33mGET /path_to_twitter_icon.png HTTP/1.1[0m" 404 -
INFO:werkzeug:127.0.0.1 - - [09/Nov/2023 16:22:18] "[33mGET /path_to_instagram_icon.png HTTP/1.1[0m" 404 -
INFO:werkzeug:127.0.0.1 - - [09/Nov/2023 16:22:18] "[36mGET /static/js/main.js HTTP/1.1[0m" 304 -
ERROR:root:Prediction error: in user code:

    File "C:\Users\Karthikeya\AppData\Local\Programs\Python\Python310\lib\site-packages\keras\src\engine\training.py", line 2416, in predict_function  *
        return step_function(self, iterator)
    File "C:\Users\Karthikeya\AppData\Local\Programs\Python\Python310\lib\site-packages\keras\src\engine\training.py", line 2401, in step_function  **
        outputs = model.distribute_strategy.run(run_step, args=(data,))
    File "C:\Users\Karthikeya\AppData\Local\Programs\Python\Python310\lib\site-packages\keras\src\engine\training.py", line 2389, in run_step  **
        outputs = model.predict_step(data)
    File "C:\Users\Karthikeya\AppData\Local\Programs\Python\Python310\lib\site-packages\keras\src\engine\training.py", line 2357, in predict_step
        return self(x, training=False)
    File "C:\Users\Karthikeya\AppData\Local\Programs\Python\Python310\lib\site-packages\keras\src\utils\traceback_utils.py", line 70, in error_handler
        raise e.with_traceback(filtered_tb) from None
    File "C:\Users\Karthikeya\AppData\Local\Programs\Python\Python310\lib\site-packages\keras\src\engine\input_spec.py", line 298, in assert_input_compatibility
        raise ValueError(

    ValueError: Input 0 of layer "model_2" is incompatible with the layer: expected shape=(None, 224, 224, 3), found shape=(None, 64, 64, 3)

ERROR:root:Prediction error: in user code:

    File "C:\Users\Karthikeya\AppData\Local\Programs\Python\Python310\lib\site-packages\keras\src\engine\training.py", line 2416, in predict_function  *
        return step_function(self, iterator)
    File "C:\Users\Karthikeya\AppData\Local\Programs\Python\Python310\lib\site-packages\keras\src\engine\training.py", line 2401, in step_function  **
        outputs = model.distribute_strategy.run(run_step, args=(data,))
    File "C:\Users\Karthikeya\AppData\Local\Programs\Python\Python310\lib\site-packages\keras\src\engine\training.py", line 2389, in run_step  **
        outputs = model.predict_step(data)
    File "C:\Users\Karthikeya\AppData\Local\Programs\Python\Python310\lib\site-packages\keras\src\engine\training.py", line 2357, in predict_step
        return self(x, training=False)
    File "C:\Users\Karthikeya\AppData\Local\Programs\Python\Python310\lib\site-packages\keras\src\utils\traceback_utils.py", line 70, in error_handler
        raise e.with_traceback(filtered_tb) from None
    File "C:\Users\Karthikeya\AppData\Local\Programs\Python\Python310\lib\site-packages\keras\src\engine\input_spec.py", line 298, in assert_input_compatibility
        raise ValueError(

    ValueError: Input 0 of layer "model_2" is incompatible with the layer: expected shape=(None, 224, 224, 3), found shape=(None, 64, 64, 3)

INFO:werkzeug:127.0.0.1 - - [09/Nov/2023 16:22:23] "[35m[1mPOST /predict HTTP/1.1[0m" 500 -
INFO:werkzeug:127.0.0.1 - - [09/Nov/2023 16:22:23] "[35m[1mPOST /predict HTTP/1.1[0m" 500 -
INFO:werkzeug: * Detected change in 'c:\\Users\\Karthikeya\\PycharmProjects\\project_AI\\app.py', reloading
